<?xml version="1.0"?>

<robot name="nw_mybot_00" xmlns:xacro="http://ros.org/wiki/xacro">

    <material name="black">
        <color rgba="0 0 0 1"/>
    </material>

    <material name="yellow">
        <color rgba="1 1 0 1"/>
    </material>

    <material name="white">
        <color rgba="1 1 1 1"/>
    </material>

    <material name="red">
        <color rgba="1 0 0 1"/>
    </material>

    <material name="green">
        <color rgba="0 1 0 1"/>
    </material>

    <material name="blue">
        <color rgba="0 0 1 1"/>
    </material>

    <material name="grey">
        <color rgba=".2 .2 .2 1"/>
    </material>

    <material name="FF6666">
        <color rgba="255 102 102 1"/>
    </material>

    <!-- <link name="base_footprint"/> -->
    <link name="base_link">
        <visual>
            <origin rpy="0 0 0" xyz="0 0 0"/>
            <geometry>
                <box size="2 1 .5"/>
            </geometry>
            <material name="white"/>
        </visual>

        <collision name="collision">
            <origin rpy="0 0 0" xyz="0 0 0"/>
            <geometry>
                <box size="2 1 0.7"/>
            </geometry>
        </collision>

        <inertial>
            <mass value="20.0"/>
            <origin rpy="0 0 0" xyz="0 0 0"/>
            <inertia ixx="0.1" ixy="0" ixz="0" iyy="0.1" iyz="0" izz="0.1"/>
        </inertial>
    </link>

    <link name="wheel_right">
        <visual>
            <origin rpy="1.5707 0 0" xyz="0 .12 0"/>
            <geometry>
                <cylinder length="0.2" radius="0.45"/>
                <!-- <mesh filename="/home/nw/Desktop/test/lifffft.stl" scale="1 1 1"/> -->

            </geometry>
            <material name="blue"/>
        </visual>

        <collision name="collision">
            <origin rpy="1.5707 0 0" xyz="0 .12 0"/>
            <geometry>
                <cylinder length="0.2" radius="0.5"/>
            </geometry>
        </collision>
    
        <inertial>
            <origin rpy="1.5707 0 0" xyz="0 .12 0"/>
            <mass value="5"/>
            <inertia ixx=".1" ixy="0.0" ixz="0.0" iyy=".1" iyz="0.0" izz=".1"/>
        </inertial>
    </link>

    <joint name="wheel_right_hinge" type="continuous">
        <origin rpy="0 0 0" xyz="0 .5 0"/>
        <child link="wheel_right"/>
        <parent link="base_link"/>
        <axis rpy="0 0 0" xyz="0 1 0"/>
        <limit effort="10000" velocity="1000"/>
        <joint_properties damping="1.0" friction="1.0"/>
    </joint>

    <link name="wheel_left">
        <visual>
            <origin rpy="1.5707 0 0" xyz="0 -.12 0"/>
            <geometry>
                <cylinder length="0.2" radius="0.45"/>
            </geometry>
            <material name="red"/>
        </visual>
    
        <collision name="collision">
            <origin rpy="1.5707 0 0" xyz="0 -.12 0"/>
            <geometry>
                <cylinder length="0.2" radius="0.5"/>
            </geometry>
        </collision>

        <inertial>
            <origin rpy="1.5707 0 0" xyz="0 -.12 0"/>
            <mass value="5"/>
            <inertia ixx=".1" ixy="0.0" ixz="0.0" iyy=".1" iyz="0.0" izz=".1"/>
        </inertial>
    </link>

    <joint name="wheel_left_hinge" type="continuous">
        <origin rpy="0 0 0" xyz="0 -0.5 0"/>
        <child link="wheel_left"/>
        <parent link="base_link"/>
        <axis rpy="0 0 0" xyz="0 1 0"/>
        <limit effort="10000" velocity="1000"/>
        <joint_properties damping="1.0" friction="1.0"/>
    </joint>

    <link name="isfront">
        <visual>
            <origin rpy="0 0 0" xyz="0.5 0 .4"/>
            <geometry>
                <cylinder length="0.3" radius=".3"/>
            </geometry>
            <material name="black"/>
        </visual>
    </link>

    <joint name="isfront_hinge" type="fixed">
        <origin rpy="0 0 0" xyz="0 0 0"/>
        <child link="isfront"/>
        <parent link="base_link"/>
        <axis rpy="0 0 0" xyz="0 1 0"/>
        <limit effort="10000" velocity="1000"/>
        <joint_properties damping="1.0" friction="1.0"/>
    </joint>


</robot>
